Workbook

Sheet Worksheet 1 (Noun)
B5: Noun refers to a name of person,animal,thing,place,event and idea.
B9: NAME: | Y9: Score:
D10: Time: | F10: =NOW() -> 45964.734 | O10: Date: | Q10: =TODAY() -> 45964 | Y10: no. | AA10: =RANDBETWEEN(1,99) -> 98 | AB10: =RANDBETWEEN(1,99) -> 16
B13: I. Select and circle one noun in each number.
AU14: 1 | AV14: 2 | AW14: 3 | AX14: 4 | AY14: 5 | AZ14: 6 | BA14: 7 | BB14: 8 | BC14: 9 | BD14: 10 | BE14: 11 | BF14: 12 | BG14: 13 | BH14: 14 | BI14: 15 | BJ14: 16 | BK14: 17 | BL14: 18 | BM14: 19 | BN14: 20 | BO14: 21 | BP14: 22 | BQ14: 23 | BR14: 24 | BS14: 25 | BT14: 26
A15: =RANDBETWEEN(1,7) -> 6 | B15: =RANK(A15,$A$15:$A$21,0)+COUNTIF($A$15:A15,A15)-1 -> 1 | C15: 1 | D15: =_xlfn.IFERROR(INDEX('SELECTION '!$E$4:$K$253,MATCH($B$15,'SELECTION '!$D$4:$D$253,0),MATCH(AU15,'SELECTION '!$E$3:$K$3,0)),"") -> jump rope | K15: =_xlfn.IFERROR(INDEX('SELECTION '!$E$4:$K$253,MATCH($B$15,'SELECTION '!$D$4:$D$253,0),MATCH(BB15,'SELECTION '!$E$3:$K$3,0)),"") -> rub | R15: =_xlfn.IFERROR(INDEX('SELECTION '!$E$4:$K$253,MATCH($B$15,'SELECTION '!$D$4:$D$253,0),MATCH(BI15,'SELECTION '!$E$3:$K$3,0)),"") -> our | Y15: =_xlfn.IFERROR(INDEX('SELECTION '!$E$4:$K$253,MATCH($B$15,'SELECTION '!$D$4:$D$253,0),MATCH(BP15,'SELECTION '!$E$3:$K$3,0)),"") -> tame | AG15: =RANDBETWEEN(1,4) -> 4 | AH15: =RANDBETWEEN(1,4) -> 3 | AI15: =RANDBETWEEN(1,4) -> 4 | AJ15: =RANDBETWEEN(1,4) -> 1 | AN15: =RANK(AG15,$AG$15:$AJ$15,0)+COUNTIF($AG$15:AG15,AG15)-1 -> 1 | AO15: =RANK(AH15,$AG$15:$AJ$15,0)+COUNTIF($AG$15:AH15,AH15)-1 -> 3 | AP15: =RANK(AI15,$AG$15:$AJ$15,0)+COUNTIF($AG$15:AI15,AI15)-1 -> 2 | AQ15: =RANK(AJ15,$AG$15:$AJ$15,0)+COUNTIF($AG$15:AJ15,AJ15)-1 -> 4 | AU15: =AN15 -> 1 | BB15: =AO15 -> 3 | BI15: =AP15 -> 2 | BP15: =AQ15 -> 4
A16: =RANDBETWEEN(1,7) -> 3 | B16: =RANK(A16,$A$15:$A$21,0)+COUNTIF($A$15:A16,A16)-1 -> 5 | C16: 2 | D16: =_xlfn.IFERROR(INDEX('SELECTION '!$E$4:$K$253,MATCH($B$16,'SELECTION '!$D$4:$D$253,0),MATCH(AU16,'SELECTION '!$E$3:$K$3,0)),"") -> direct | K16: =_xlfn.IFERROR(INDEX('SELECTION '!$E$4:$K$253,MATCH($B$16,'SELECTION '!$D$4:$D$253,0),MATCH(BB16,'SELECTION '!$E$3:$K$3,0)),"") -> taxi | R16: =_xlfn.IFERROR(INDEX('SELECTION '!$E$4:$K$253,MATCH($B$16,'SELECTION '!$D$4:$D$253,0),MATCH(BI16,'SELECTION '!$E$3:$K$3,0)),"") -> whosoever | Y16: =_xlfn.IFERROR(INDEX('SELECTION '!$E$4:$K$253,MATCH($B$16,'SELECTION '!$D$4:$D$253,0),MATCH(BP16,'SELECTION '!$E$3:$K$3,0)),"") -> serious | AG16: =RANDBETWEEN(1,4) -> 1 | AH16: =RANDBETWEEN(1,4) -> 2 | AI16: =RANDBETWEEN(1,4) -> 2 | AJ16: =RANDBETWEEN(1,4) -> 1 | AN16: =RANK(AG16,$AG$16:$AJ$16,0)+COUNTIF($AG$16:AG16,AG16)-1 -> 3 | AO16: =RANK(AH16,$AG$16:$AJ$16,0)+COUNTIF($AG$16:AH16,AH16)-1 -> 1 | AP16: =RANK(AI16,$AG$16:$AJ$16,0)+COUNTIF($AG$16:AI16,AI16)-1 -> 2 | AQ16: =RANK(AJ16,$AG$16:$AJ$16,0)+COUNTIF($AG$16:AJ16,AJ16)-1 -> 4 | AU16: =AN16 -> 3 | BB16: =AO16 -> 1 | BI16: =AP16 -> 2 | BP16: =AQ16 -> 4
A17: =RANDBETWEEN(1,7) -> 3 | B17: =RANK(A17,$A$15:$A$21,0)+COUNTIF($A$15:A17,A17)-1 -> 6 | C17: 3 | D17: =_xlfn.IFERROR(INDEX('SELECTION '!$E$4:$K$253,MATCH($B$17,'SELECTION '!$D$4:$D$253,0),MATCH(AU17,'SELECTION '!$E$3:$K$3,0)),"") -> leaf | K17: =_xlfn.IFERROR(INDEX('SELECTION '!$E$4:$K$253,MATCH($B$17,'SELECTION '!$D$4:$D$253,0),MATCH(BB17,'SELECTION '!$E$3:$K$3,0)),"") -> whoever | R17: =_xlfn.IFERROR(INDEX('SELECTION '!$E$4:$K$253,MATCH($B$17,'SELECTION '!$D$4:$D$253,0),MATCH(BI17,'SELECTION '!$E$3:$K$3,0)),"") -> plant | Y17: =_xlfn.IFERROR(INDEX('SELECTION '!$E$4:$K$253,MATCH($B$17,'SELECTION '!$D$4:$D$253,0),MATCH(BP17,'SELECTION '!$E$3:$K$3,0)),"") -> beautiful | AG17: =RANDBETWEEN(1,4) -> 3 | AH17: =RANDBETWEEN(1,4) -> 1 | AI17: =RANDBETWEEN(1,4) -> 1 | AJ17: =RANDBETWEEN(1,4) -> 1 | AN17: =RANK(AG17,$AG$17:$AJ$17,0)+COUNTIF($AG$17:AG17,AG17)-1 -> 1 | AO17: =RANK(AH17,$AG$17:$AJ$17,0)+COUNTIF($AG$17:AH17,AH17)-1 -> 2 | AP17: =RANK(AI17,$AG$17:$AJ$17,0)+COUNTIF($AG$17:AI17,AI17)-1 -> 3 | AQ17: =RANK(AJ17,$AG$17:$AJ$17,0)+COUNTIF($AG$17:AJ17,AJ17)-1 -> 4 | AU17: =AN17 -> 1 | BB17: =AO17 -> 2 | BI17: =AP17 -> 3 | BP17: =AQ17 -> 4
A18: =RANDBETWEEN(1,7) -> 4 | B18: =RANK(A18,$A$15:$A$21,0)+COUNTIF($A$15:A18,A18)-1 -> 3 | C18: 4 | D18: =_xlfn.IFERROR(INDEX('SELECTION '!$E$4:$K$253,MATCH($B$18,'SELECTION '!$D$4:$D$253,0),MATCH(AU18,'SELECTION '!$E$3:$K$3,0)),"") -> park | K18: =_xlfn.IFERROR(INDEX('SELECTION '!$E$4:$K$253,MATCH($B$18,'SELECTION '!$D$4:$D$253,0),MATCH(BB18,'SELECTION '!$E$3:$K$3,0)),"") -> it | R18: =_xlfn.IFERROR(INDEX('SELECTION '!$E$4:$K$253,MATCH($B$18,'SELECTION '!$D$4:$D$253,0),MATCH(BI18,'SELECTION '!$E$3:$K$3,0)),"") -> smooth | Y18: =_xlfn.IFERROR(INDEX('SELECTION '!$E$4:$K$253,MATCH($B$18,'SELECTION '!$D$4:$D$253,0),MATCH(BP18,'SELECTION '!$E$3:$K$3,0)),"") -> follow | AG18: =RANDBETWEEN(1,4) -> 3 | AH18: =RANDBETWEEN(1,4) -> 3 | AI18: =RANDBETWEEN(1,4) -> 1 | AJ18: =RANDBETWEEN(1,4) -> 2 | AN18: =RANK(AG18,$AG$18:$AJ$18,0)+COUNTIF($AG$18:AG18,AG18)-1 -> 1 | AO18: =RANK(AH18,$AG$18:$AJ$18,0)+COUNTIF($AG$18:AH18,AH18)-1 -> 2 | AP18: =RANK(AI18,$AG$18:$AJ$18,0)+COUNTIF($AG$18:AI18,AI18)-1 -> 4 | AQ18: =RANK(AJ18,$AG$18:$AJ$18,0)+COUNTIF($AG$18:AJ18,AJ18)-1 -> 3 | AU18: =AN18 -> 1 | BB18: =AO18 -> 2 | BI18: =AP18 -> 4 | BP18: =AQ18 -> 3
A19: =RANDBETWEEN(1,7) -> 4 | B19: =RANK(A19,$A$15:$A$21,0)+COUNTIF($A$15:A19,A19)-1 -> 4 | C19: 5 | D19: =_xlfn.IFERROR(INDEX('SELECTION '!$E$4:$K$253,MATCH($B$19,'SELECTION '!$D$4:$D$253,0),MATCH(AU19,'SELECTION '!$E$3:$K$3,0)),"") -> ourselves | K19: =_xlfn.IFERROR(INDEX('SELECTION '!$E$4:$K$253,MATCH($B$19,'SELECTION '!$D$4:$D$253,0),MATCH(BB19,'SELECTION '!$E$3:$K$3,0)),"") -> fan | R19: =_xlfn.IFERROR(INDEX('SELECTION '!$E$4:$K$253,MATCH($B$19,'SELECTION '!$D$4:$D$253,0),MATCH(BI19,'SELECTION '!$E$3:$K$3,0)),"") -> test | Y19: =_xlfn.IFERROR(INDEX('SELECTION '!$E$4:$K$253,MATCH($B$19,'SELECTION '!$D$4:$D$253,0),MATCH(BP19,'SELECTION '!$E$3:$K$3,0)),"") -> grumpy | AG19: =RANDBETWEEN(1,4) -> 3 | AH19: =RANDBETWEEN(1,4) -> 4 | AI19: =RANDBETWEEN(1,4) -> 3 | AJ19: =RANDBETWEEN(1,4) -> 2 | AN19: =RANK(AG19,$AG$19:$AJ$19,0)+COUNTIF($AG$19:AG19,AG19)-1 -> 2 | AO19: =RANK(AH19,$AG$19:$AJ$19,0)+COUNTIF($AG$19:AH19,AH19)-1 -> 1 | AP19: =RANK(AI19,$AG$19:$AJ$19,0)+COUNTIF($AG$19:AI19,AI19)-1 -> 3 | AQ19: =RANK(AJ19,$AG$19:$AJ$19,0)+COUNTIF($AG$19:AJ19,AJ19)-1 -> 4 | AU19: =AN19 -> 2 | BB19: =AO19 -> 1 | BI19: =AP19 -> 3 | BP19: =AQ19 -> 4
A20: =RANDBETWEEN(1,7) -> 6 | B20: =RANK(A20,$A$15:$A$21,0)+COUNTIF($A$15:A20,A20)-1 -> 2 | C20: 6 | D20: =_xlfn.IFERROR(INDEX('SELECTION '!$E$4:$K$253,MATCH($B$20,'SELECTION '!$D$4:$D$253,0),MATCH(AU20,'SELECTION '!$E$3:$K$3,0)),"") -> serious | K20: =_xlfn.IFERROR(INDEX('SELECTION '!$E$4:$K$253,MATCH($B$20,'SELECTION '!$D$4:$D$253,0),MATCH(BB20,'SELECTION '!$E$3:$K$3,0)),"") -> we | R20: =_xlfn.IFERROR(INDEX('SELECTION '!$E$4:$K$253,MATCH($B$20,'SELECTION '!$D$4:$D$253,0),MATCH(BI20,'SELECTION '!$E$3:$K$3,0)),"") -> gear | Y20: =_xlfn.IFERROR(INDEX('SELECTION '!$E$4:$K$253,MATCH($B$20,'SELECTION '!$D$4:$D$253,0),MATCH(BP20,'SELECTION '!$E$3:$K$3,0)),"") -> find | AG20: =RANDBETWEEN(1,4) -> 1 | AH20: =RANDBETWEEN(1,4) -> 2 | AI20: =RANDBETWEEN(1,4) -> 3 | AJ20: =RANDBETWEEN(1,4) -> 2 | AN20: =RANK(AG20,$AG$20:$AJ$20,0)+COUNTIF($AG$20:AG20,AG20)-1 -> 4 | AO20: =RANK(AH20,$AG$20:$AJ$20,0)+COUNTIF($AG$20:AH20,AH20)-1 -> 2 | AP20: =RANK(AI20,$AG$20:$AJ$20,0)+COUNTIF($AG$20:AI20,AI20)-1 -> 1 | AQ20: =RANK(AJ20,$AG$20:$AJ$20,0)+COUNTIF($AG$20:AJ20,AJ20)-1 -> 3 | AU20: =AN20 -> 4 | BB20: =AO20 -> 2 | BI20: =AP20 -> 1 | BP20: =AQ20 -> 3
A21: =RANDBETWEEN(1,7) -> 2 | B21: =RANK(A21,$A$15:$A$21,0)+COUNTIF($A$15:A21,A21)-1 -> 7 | C21: 7 | D21: =_xlfn.IFERROR(INDEX('SELECTION '!$E$4:$K$253,MATCH($B$21,'SELECTION '!$D$4:$D$253,0),MATCH(AU21,'SELECTION '!$E$3:$K$3,0)),"") -> manage | K21: =_xlfn.IFERROR(INDEX('SELECTION '!$E$4:$K$253,MATCH($B$21,'SELECTION '!$D$4:$D$253,0),MATCH(BB21,'SELECTION '!$E$3:$K$3,0)),"") -> that | R21: =_xlfn.IFERROR(INDEX('SELECTION '!$E$4:$K$253,MATCH($B$21,'SELECTION '!$D$4:$D$253,0),MATCH(BI21,'SELECTION '!$E$3:$K$3,0)),"") -> gloves | Y21: =_xlfn.IFERROR(INDEX('SELECTION '!$E$4:$K$253,MATCH($B$21,'SELECTION '!$D$4:$D$253,0),MATCH(BP21,'SELECTION '!$E$3:$K$3,0)),"") -> graceful | AG21: =RANDBETWEEN(1,4) -> 1 | AH21: =RANDBETWEEN(1,4) -> 3 | AI21: =RANDBETWEEN(1,4) -> 4 | AJ21: =RANDBETWEEN(1,4) -> 1 | AN21: =RANK(AG21,$AG$21:$AJ$21,0)+COUNTIF($AG$21:AG21,AG21)-1 -> 3 | AO21: =RANK(AH21,$AG$21:$AJ$21,0)+COUNTIF($AG$21:AH21,AH21)-1 -> 2 | AP21: =RANK(AI21,$AG$21:$AJ$21,0)+COUNTIF($AG$21:AI21,AI21)-1 -> 1 | AQ21: =RANK(AJ21,$AG$21:$AJ$21,0)+COUNTIF($AG$21:AJ21,AJ21)-1 -> 4 | AU21: =AN21 -> 3 | BB21: =AO21 -> 2 | BI21: =AP21 -> 1 | BP21: =AQ21 -> 4
B22: =RANK(A22,$A$15:$A$22,0)+COUNTIF($A$15:A22,A22)-1 -> #N/A | AG22: =RANDBETWEEN(1,4) -> 3 | AH22: =RANDBETWEEN(1,4) -> 3 | AI22: =RANDBETWEEN(1,4) -> 4 | AJ22: =RANDBETWEEN(1,4) -> 1 | AN22: =RANK(AG22,$AG$22:$AJ$22,0)+COUNTIF($AG$22:AG22,AG22)-1 -> 2 | AO22: =RANK(AH22,$AG$22:$AJ$22,0)+COUNTIF($AG$22:AH22,AH22)-1 -> 3 | AP22: =RANK(AI22,$AG$22:$AJ$22,0)+COUNTIF($AG$22:AI22,AI22)-1 -> 1 | AQ22: =RANK(AJ22,$AG$22:$AJ$22,0)+COUNTIF($AG$22:AJ22,AJ22)-1 -> 4 | AU22: =AN22 -> 2 | BB22: =AO22 -> 3 | BI22: =AP22 -> 1 | BP22: =AQ22 -> 4
B23: II. Underline the noun in a sentence.
A25: =RANDBETWEEN(1,10) -> 5 | B25: =RANK(A25,$A$25:$A$33,0)+COUNTIF($A$25:A25,A25)-1 -> 6 | C25: 1.) | D25: =INDEX('SENTENCE NOUN'!$E$4:$E$203,MATCH(B25,'SENTENCE NOUN'!$D$4:$D$203,0)) -> I sharpened the pencil again.
A26: =RANDBETWEEN(1,10) -> 9 | B26: =RANK(A26,$A$25:$A$33,0)+COUNTIF($A$25:A26,A26)-1 -> 1 | C26: 2.) | D26: =INDEX('SENTENCE NOUN'!$E$4:$E$203,MATCH(B26,'SENTENCE NOUN'!$D$4:$D$203,0)) -> They picked up the egg.
A27: =RANDBETWEEN(1,10) -> 8 | B27: =RANK(A27,$A$25:$A$33,0)+COUNTIF($A$25:A27,A27)-1 -> 2 | C27: 3.) | D27: =INDEX('SENTENCE NOUN'!$E$4:$E$203,MATCH(B27,'SENTENCE NOUN'!$D$4:$D$203,0)) -> They shook the bag hard.
A28: =RANDBETWEEN(1,10) -> 6 | B28: =RANK(A28,$A$25:$A$33,0)+COUNTIF($A$25:A28,A28)-1 -> 4 | C28: 4.) | D28: =INDEX('SENTENCE NOUN'!$E$4:$E$203,MATCH(B28,'SENTENCE NOUN'!$D$4:$D$203,0)) -> Quickly, she grabbed the hat.
A29: =RANDBETWEEN(1,10) -> 3 | B29: =RANK(A29,$A$25:$A$33,0)+COUNTIF($A$25:A29,A29)-1 -> 9 | C29: 5.) | D29: =INDEX('SENTENCE NOUN'!$E$4:$E$203,MATCH(B29,'SENTENCE NOUN'!$D$4:$D$203,0)) -> He stirred the pot slowly.
A30: =RANDBETWEEN(1,10) -> 5 | B30: =RANK(A30,$A$25:$A$33,0)+COUNTIF($A$25:A30,A30)-1 -> 7 | C30: 6.) | D30: =INDEX('SENTENCE NOUN'!$E$4:$E$203,MATCH(B30,'SENTENCE NOUN'!$D$4:$D$203,0)) -> He is washing the sock.
A31: =RANDBETWEEN(1,10) -> 6 | B31: =RANK(A31,$A$25:$A$33,0)+COUNTIF($A$25:A31,A31)-1 -> 5 | C31: 7.) | D31: =INDEX('SENTENCE NOUN'!$E$4:$E$203,MATCH(B31,'SENTENCE NOUN'!$D$4:$D$203,0)) -> The bell rang very loudly.
A32: =RANDBETWEEN(1,10) -> 4 | B32: =RANK(A32,$A$25:$A$33,0)+COUNTIF($A$25:A32,A32)-1 -> 8
A33: =RANDBETWEEN(1,10) -> 8 | B33: III. Draw the noun : Draw the noun inside the box.
C36: =INDEX('SELECTION '!$E$4:$E$253,MATCH(AK47,'SELECTION '!$D$4:$D$253,0)) -> tree | M36: =INDEX('SELECTION '!$E$4:$E$253,MATCH(AK48,'SELECTION '!$D$4:$D$253,0)) -> lion | W36: =INDEX('SELECTION '!$E$4:$E$253,MATCH(AK49,'SELECTION '!$D$4:$D$253,0)) -> girl | AI36: =RANDBETWEEN(1,6) -> 4 | AJ36: =RANK(AI36,$AI$36:$AI$41,0)+COUNTIF($AI$36:AI36,AI36)-1 -> 2 | AK36: 11 | AL36: =RANK(AI36,$AI$36:$AI$41,0)+COUNTIF($AI$36:AI36,AI36)-1 -> 2
AI37: =RANDBETWEEN(1,6) -> 2 | AJ37: =RANK(AI37,$AI$36:$AI$41,0)+COUNTIF($AI$36:AI37,AI37)-1 -> 4 | AK37: 12 | AL37: =RANK(AI37,$AI$36:$AI$41,0)+COUNTIF($AI$36:AI37,AI37)-1 -> 4
AI38: =RANDBETWEEN(1,6) -> 1 | AJ38: =RANK(AI38,$AI$36:$AI$41,0)+COUNTIF($AI$36:AI38,AI38)-1 -> 5 | AK38: 13 | AL38: =RANK(AI38,$AI$36:$AI$41,0)+COUNTIF($AI$36:AI38,AI38)-1 -> 5
AI39: =RANDBETWEEN(1,6) -> 5 | AJ39: =RANK(AI39,$AI$36:$AI$41,0)+COUNTIF($AI$36:AI39,AI39)-1 -> 1 | AK39: 14 | AL39: =RANK(AI39,$AI$36:$AI$41,0)+COUNTIF($AI$36:AI39,AI39)-1 -> 1
AI40: =RANDBETWEEN(1,6) -> 4 | AJ40: =RANK(AI40,$AI$36:$AI$41,0)+COUNTIF($AI$36:AI40,AI40)-1 -> 3 | AK40: 15 | AL40: =RANK(AI40,$AI$36:$AI$41,0)+COUNTIF($AI$36:AI40,AI40)-1 -> 3
AI41: =RANDBETWEEN(1,6) -> 1 | AJ41: =RANK(AI41,$AI$36:$AI$41,0)+COUNTIF($AI$36:AI41,AI41)-1 -> 6 | AK41: 16 | AL41: =RANK(AI41,$AI$36:$AI$41,0)+COUNTIF($AI$36:AI41,AI41)-1 -> 6
C47: =INDEX('SELECTION '!$E$4:$E$253,MATCH(AK50,'SELECTION '!$D$4:$D$253,0)) -> uniform | M47: =INDEX('SELECTION '!$E$4:$E$253,MATCH(AK51,'SELECTION '!$D$4:$D$253,0)) -> sandals | W47: =INDEX('SELECTION '!$E$4:$E$253,MATCH(AK52,'SELECTION '!$D$4:$D$253,0)) -> watermelon | AI47: =RANDBETWEEN(1,6) -> 6 | AJ47: =RANK(AI47,$AI$47:$AI$52,0)+COUNTIF($AI$47:AI47,AI47)-1 -> 1 | AK47: =INDEX($AK$36:$AK$41,MATCH(AJ47,$AJ$36:$AJ$41,0)) -> 14
AI48: =RANDBETWEEN(1,6) -> 2 | AJ48: =RANK(AI48,$AI$47:$AI$52,0)+COUNTIF($AI$47:AI48,AI48)-1 -> 6 | AK48: =INDEX($AK$36:$AK$41,MATCH(AJ48,$AJ$36:$AJ$41,0)) -> 16
AI49: =RANDBETWEEN(1,6) -> 4 | AJ49: =RANK(AI49,$AI$47:$AI$52,0)+COUNTIF($AI$47:AI49,AI49)-1 -> 3 | AK49: =INDEX($AK$36:$AK$41,MATCH(AJ49,$AJ$36:$AJ$41,0)) -> 15
AI50: =RANDBETWEEN(1,6) -> 4 | AJ50: =RANK(AI50,$AI$47:$AI$52,0)+COUNTIF($AI$47:AI50,AI50)-1 -> 4 | AK50: =INDEX($AK$36:$AK$41,MATCH(AJ50,$AJ$36:$AJ$41,0)) -> 12
AI51: =RANDBETWEEN(1,6) -> 3 | AJ51: =RANK(AI51,$AI$47:$AI$52,0)+COUNTIF($AI$47:AI51,AI51)-1 -> 5 | AK51: =INDEX($AK$36:$AK$41,MATCH(AJ51,$AJ$36:$AJ$41,0)) -> 13
AI52: =RANDBETWEEN(1,6) -> 5 | AJ52: =RANK(AI52,$AI$47:$AI$52,0)+COUNTIF($AI$47:AI52,AI52)-1 -> 2 | AK52: =INDEX($AK$36:$AK$41,MATCH(AJ52,$AJ$36:$AJ$41,0)) -> 11
B60: Answer key | G60: no. | H60: =AA10 -> 98 | I60: =AB10 -> 16 | K60: Time: | M60: =F10 -> 45964.734 | S60: Date: | U60: =Q10 -> 45964
B61: I. Select and circle one noun in each number
B62: =B15 -> 1 | C62: 1 | D62: =INDEX('SELECTION '!$E$4:$E$253,MATCH(B62,'SELECTION '!$D$4:$D$253,0)) -> jump rope
B63: =B16 -> 5 | C63: 2 | D63: =INDEX('SELECTION '!$E$4:$E$253,MATCH(B63,'SELECTION '!$D$4:$D$253,0)) -> taxi
B64: =B17 -> 6 | C64: 3 | D64: =INDEX('SELECTION '!$E$4:$E$253,MATCH(B64,'SELECTION '!$D$4:$D$253,0)) -> leaf
...

Sheet Worksheet 2 (Noun)
B9: NAME: | Y9: Score:
D10: Time: | F10: =NOW() -> 45964.734 | O10: Date: | Q10: =TODAY() -> 45964 | Y10: no. | AA10: =RANDBETWEEN(1,99) -> 81 | AB10: =RANDBETWEEN(1,99) -> 83
B12: I. Identify the noun inside the box whether it is the name of person,animal,place,thing and event and put it in the provided correct column.
A13: =RANDBETWEEN(1,10) -> 8
A14: =RANDBETWEEN(1,10) -> 3 | I14: =INDEX(Sheet1!$M$2:$M$15,MATCH(AI14,Sheet1!$K$2:$K$15,0)) -> duck | O14: =INDEX(Sheet1!$M$2:$M$15,MATCH(AJ14,Sheet1!$K$2:$K$15,0)) -> airport | U14: =INDEX(Sheet1!$M$2:$M$15,MATCH(AK14,Sheet1!$K$2:$K$15,0)) -> meeting | AH14: 1 | AI14: 2 | AJ14: 3 | AK14: 4 | AL14: 5 | AM14: 6 | AN14: 7 | AO14: 8 | AP14: 9 | AQ14: 10 | AR14: 11 | AS14: 12 | AT14: 13 | AU14: 14
A15: =RANDBETWEEN(1,10) -> 9 | F15: =INDEX(Sheet1!$M$2:$M$15,MATCH(AM14,Sheet1!$K$2:$K$15,0)) -> table | L15: =INDEX(Sheet1!$M$2:$M$15,MATCH(AN14,Sheet1!$K$2:$K$15,0)) -> restaurant | R15: =INDEX(Sheet1!$M$2:$M$15,MATCH(AO14,Sheet1!$K$2:$K$15,0)) -> release | X15: =INDEX(Sheet1!$M$2:$M$15,MATCH(AP14,Sheet1!$K$2:$K$15,0)) -> nurse
A16: =RANDBETWEEN(1,10) -> 3 | C16: =INDEX(Sheet1!$M$2:$M$15,MATCH(AQ14,Sheet1!$K$2:$K$15,0)) -> needle | I16: =INDEX(Sheet1!$M$2:$M$15,MATCH(AR14,Sheet1!$K$2:$K$15,0)) -> painter | O16: =INDEX(Sheet1!$M$2:$M$15,MATCH(AS14,Sheet1!$K$2:$K$15,0)) -> ant | U16: =INDEX(Sheet1!$M$2:$M$15,MATCH(AT14,Sheet1!$K$2:$K$15,0)) -> photographer
A17: =RANDBETWEEN(1,10) -> 5 | F17: =INDEX(Sheet1!$M$2:$M$15,MATCH(AH14,Sheet1!$K$2:$K$15,0)) -> flamingo | L17: =INDEX(Sheet1!$M$2:$M$15,MATCH(AU14,Sheet1!$K$2:$K$15,0)) -> shoes | X17: =INDEX(Sheet1!$M$2:$M$15,MATCH(AL14,Sheet1!$K$2:$K$15,0)) -> subway
A18: =RANDBETWEEN(1,10) -> 2
A19: =RANDBETWEEN(1,10) -> 4
A20: =RANDBETWEEN(1,10) -> 6 | C20: Person | I20: Animal | O20: Place | U20: Thing | AA20: Event
A21: =RANDBETWEEN(1,10) -> 3
A22: =RANDBETWEEN(1,10) -> 2
A25: =RANDBETWEEN(1,10) -> 2 | B25: II. Find the Noun in the sentence and draw it in the box.
A26: =RANDBETWEEN(1,10) -> 8 | F26: =INDEX('SENTENCE NOUN'!$E$4:$E$203,MATCH(AJ37,'SENTENCE NOUN'!$D$4:$D$203,0)) -> They shook the bag hard. | U26: =INDEX('SENTENCE NOUN'!$E$4:$E$203,MATCH(AJ38,'SENTENCE NOUN'!$D$4:$D$203,0)) -> They picked up the egg.
A27: =RANDBETWEEN(1,10) -> 4
A28: =RANDBETWEEN(1,10) -> 3
A29: =RANDBETWEEN(1,10) -> 7
A30: =RANDBETWEEN(1,10) -> 1
A31: =RANDBETWEEN(1,10) -> 4
A32: =RANDBETWEEN(1,10) -> 6
A33: =RANDBETWEEN(1,10) -> 3
A34: =RANDBETWEEN(1,10) -> 9
F35: =INDEX('SENTENCE NOUN'!$E$4:$E$203,MATCH(AJ39,'SENTENCE NOUN'!$D$4:$D$203,0)) -> He watched the kite closely. | U35: =INDEX('SENTENCE NOUN'!$E$4:$E$203,MATCH(AJ40,'SENTENCE NOUN'!$D$4:$D$203,0)) -> I sharpened the pencil again.
AI37: =RANDBETWEEN(1,6) -> 5 | AJ37: =RANK(AI37,$AI$37:$AI$42,0)+COUNTIF($AI$37:AI37,AI37)-1 -> 2 | AK37: 11 | AL37: =RANK(AI37,$AI$37:$AI$42,0)+COUNTIF($AI$37:AI37,AI37)-1 -> 2
AI38: =RANDBETWEEN(1,6) -> 6 | AJ38: =RANK(AI38,$AI$37:$AI$42,0)+COUNTIF($AI$37:AI38,AI38)-1 -> 1 | AK38: 12 | AL38: =RANK(AI38,$AI$37:$AI$42,0)+COUNTIF($AI$37:AI38,AI38)-1 -> 1
AI39: =RANDBETWEEN(1,6) -> 4 | AJ39: =RANK(AI39,$AI$37:$AI$42,0)+COUNTIF($AI$37:AI39,AI39)-1 -> 3 | AK39: 13 | AL39: =RANK(AI39,$AI$37:$AI$42,0)+COUNTIF($AI$37:AI39,AI39)-1 -> 3
AI40: =RANDBETWEEN(1,6) -> 1 | AJ40: =RANK(AI40,$AI$37:$AI$42,0)+COUNTIF($AI$37:AI40,AI40)-1 -> 6 | AK40: 14 | AL40: =RANK(AI40,$AI$37:$AI$42,0)+COUNTIF($AI$37:AI40,AI40)-1 -> 6
AI41: =RANDBETWEEN(1,6) -> 4 | AJ41: =RANK(AI41,$AI$37:$AI$42,0)+COUNTIF($AI$37:AI41,AI41)-1 -> 4 | AK41: 15 | AL41: =RANK(AI41,$AI$37:$AI$42,0)+COUNTIF($AI$37:AI41,AI41)-1 -> 4
AI42: =RANDBETWEEN(1,6) -> 3 | AJ42: =RANK(AI42,$AI$37:$AI$42,0)+COUNTIF($AI$37:AI42,AI42)-1 -> 5 | AK42: 16 | AL42: =RANK(AI42,$AI$37:$AI$42,0)+COUNTIF($AI$37:AI42,AI42)-1 -> 5
F44: =INDEX('SENTENCE NOUN'!$E$4:$E$203,MATCH(AJ41,'SENTENCE NOUN'!$D$4:$D$203,0)) -> Quickly, she grabbed the hat. | U44: =INDEX('SENTENCE NOUN'!$E$4:$E$203,MATCH(AJ42,'SENTENCE NOUN'!$D$4:$D$203,0)) -> The bell rang very loudly.
AI48: =RANDBETWEEN(1,6) -> 3 | AJ48: =RANK(AI48,$AI$48:$AI$53,0)+COUNTIF($AI$48:AI48,AI48)-1 -> 2 | AK48: =INDEX($AK$37:$AK$42,MATCH(AJ48,$AJ$37:$AJ$42,0)) -> 11
AI49: =RANDBETWEEN(1,6) -> 1 | AJ49: =RANK(AI49,$AI$48:$AI$53,0)+COUNTIF($AI$48:AI49,AI49)-1 -> 5 | AK49: =INDEX($AK$37:$AK$42,MATCH(AJ49,$AJ$37:$AJ$42,0)) -> 16
AI50: =RANDBETWEEN(1,6) -> 3 | AJ50: =RANK(AI50,$AI$48:$AI$53,0)+COUNTIF($AI$48:AI50,AI50)-1 -> 3 | AK50: =INDEX($AK$37:$AK$42,MATCH(AJ50,$AJ$37:$AJ$42,0)) -> 13
AI51: =RANDBETWEEN(1,6) -> 4 | AJ51: =RANK(AI51,$AI$48:$AI$53,0)+COUNTIF($AI$48:AI51,AI51)-1 -> 1 | AK51: =INDEX($AK$37:$AK$42,MATCH(AJ51,$AJ$37:$AJ$42,0)) -> 12
AI52: =RANDBETWEEN(1,6) -> 2 | AJ52: =RANK(AI52,$AI$48:$AI$53,0)+COUNTIF($AI$48:AI52,AI52)-1 -> 4 | AK52: =INDEX($AK$37:$AK$42,MATCH(AJ52,$AJ$37:$AJ$42,0)) -> 15
B53: III. Identify the noun whether it is Proper Noun or Common Noun. | AI53: =RANDBETWEEN(1,6) -> 1 | AJ53: =RANK(AI53,$AI$48:$AI$53,0)+COUNTIF($AI$48:AI53,AI53)-1 -> 6 | AK53: =INDEX($AK$37:$AK$42,MATCH(AJ53,$AJ$37:$AJ$42,0)) -> 14
C54: =INDEX(Sheet1!$X$2:$X$11,MATCH(AQ61,Sheet1!$V$2:$V$11,0)) -> Vice Ganda | U54: =INDEX(Sheet1!$X$2:$X$11,MATCH(AR61,Sheet1!$V$2:$V$11,0)) -> computer
F55: =INDEX(Sheet1!$X$2:$X$11,MATCH(AI61,Sheet1!$V$2:$V$11,0)) -> cashier | R55: =INDEX(Sheet1!$X$2:$X$11,MATCH(AL61,Sheet1!$V$2:$V$11,0)) -> Greenbelt
C56: =INDEX(Sheet1!$X$2:$X$11,MATCH(AJ61,Sheet1!$V$2:$V$11,0)) -> neighbor | O56: =INDEX(Sheet1!$X$2:$X$11,MATCH(AK61,Sheet1!$V$2:$V$11,0)) -> street
...

Sheet SELECTION 
E2: noun | F2: pronoun | G2: verb | H2: adjective | I2: adverb | J2: conjunction | K2: preposition | L2: interjection
E3: 1 | F3: 2 | G3: 3 | H3: 4 | I3: 5 | J3: 6 | K3: 7
A4: 1 | C4: =RANDBETWEEN(1,250) -> 99 | D4: =RANK(C4,$C$4:$C$253,0)+COUNTIF($C$4:C4,C4)-1 -> 158 | E4: boy | F4: i | G4: run | H4: happy | I4: quickly | J4: For | K4: about
A5: 2 | C5: =RANDBETWEEN(1,250) -> 237 | D5: =RANK(C5,$C$4:$C$253,0)+COUNTIF($C$4:C5,C5)-1 -> 15 | E5: girl | F5: you | G5: walk | H5: sad | I5: slowly | J5: And | K5: above
A6: 3 | C6: =RANDBETWEEN(1,250) -> 131 | D6: =RANK(C6,$C$4:$C$253,0)+COUNTIF($C$4:C6,C6)-1 -> 132 | E6: baby | F6: he | G6: jump | H6: big | I6: loudly | J6: Nor | K6: across
A7: 4 | C7: =RANDBETWEEN(1,250) -> 72 | D7: =RANK(C7,$C$4:$C$253,0)+COUNTIF($C$4:C7,C7)-1 -> 188 | E7: mom | F7: she | G7: skip | H7: small | I7: quietly | J7: But | K7: after
A8: 5 | C8: =RANDBETWEEN(1,250) -> 146 | D8: =RANK(C8,$C$4:$C$253,0)+COUNTIF($C$4:C8,C8)-1 -> 114 | E8: dad | F8: it | G8: hop | H8: fast | I8: happily | J8: Or | K8: against
A9: 6 | C9: =RANDBETWEEN(1,250) -> 130 | D9: =RANK(C9,$C$4:$C$253,0)+COUNTIF($C$4:C9,C9)-1 -> 134 | E9: teacher | F9: we | G9: climb | H9: slow | I9: sadly | J9: Yet | K9: along
A10: 7 | C10: =RANDBETWEEN(1,250) -> 14 | D10: =RANK(C10,$C$4:$C$253,0)+COUNTIF($C$4:C10,C10)-1 -> 237 | E10: doctor | F10: they | G10: slide | H10: hot | I10: angrily | J10: So | K10: among
A11: 8 | C11: =RANDBETWEEN(1,250) -> 26 | D11: =RANK(C11,$C$4:$C$253,0)+COUNTIF($C$4:C11,C11)-1 -> 229 | E11: nurse | F11: me | G11: swim | H11: cold | I11: eagerly | J11: After | K11: around
A12: 9 | C12: =RANDBETWEEN(1,250) -> 182 | D12: =RANK(C12,$C$4:$C$253,0)+COUNTIF($C$4:C12,C12)-1 -> 71 | E12: police | F12: him | G12: fly | H12: young | I12: easily | J12: Although | K12: at
A13: 10 | C13: =RANDBETWEEN(1,250) -> 231 | D13: =RANK(C13,$C$4:$C$253,0)+COUNTIF($C$4:C13,C13)-1 -> 21 | E13: firefighter | F13: her | G13: dance | H13: old | I13: hardly | J13: As | K13: before
A14: 11 | C14: =RANDBETWEEN(1,250) -> 176 | D14: =RANK(C14,$C$4:$C$253,0)+COUNTIF($C$4:C14,C14)-1 -> 78 | E14: farmer | F14: us | G14: sing | H14: new | I14: fast | J14: As if | K14: behind
A15: 12 | C15: =RANDBETWEEN(1,250) -> 234 | D15: =RANK(C15,$C$4:$C$253,0)+COUNTIF($C$4:C15,C15)-1 -> 18 | E15: chef | F15: them | G15: read | H15: long | I15: well | J15: As long as | K15: below
... A253: 250 | C253: =RANDBETWEEN(1,250) -> 239 | D253: =RANK(C253,$C$4:$C$253,0)+COUNTIF($C$4:C253,C253)-1 -> 13 | E253: sandals | F253: why | G253: relax | H253: smooth | I253: zealously | J253: Such...that | K253: instead of
D256: 3
C257: 6 | D257: =_xlfn.IFERROR(INDEX($E$4:$K$253,MATCH($C$257,D4:D253,0),MATCH(D256,$E$3:$K$3,0)),"") -> plant

Sheet Sheet2
A1: Draw 10 nouns in the box and write the name of it

Sheet SENTENCE NOUN
E3: sentence with noun
B4: 1 | C4: =RANDBETWEEN(1,199) -> 67 | D4: =RANK(C4,$C$4:$C$203,0)+COUNTIF($C$4:C4,C4)-1 -> 119 | E4: The apple fell very fast. | F4: apple
B5: 2 | C5: =RANDBETWEEN(1,199) -> 88 | D5: =RANK(C5,$C$4:$C$203,0)+COUNTIF($C$4:C5,C5)-1 -> 105 | E5: She gently kicked the ball. | F5: ball
B6: 3 | C6: =RANDBETWEEN(1,199) -> 67 | D6: =RANK(C6,$C$4:$C$203,0)+COUNTIF($C$4:C6,C6)-1 -> 120 | E6: He is hiding the kite. | F6: kite
B7: 4 | C7: =RANDBETWEEN(1,199) -> 30 | D7: =RANK(C7,$C$4:$C$203,0)+COUNTIF($C$4:C7,C7)-1 -> 156 | E7: A bird flew above us. | F7: bird
B8: 5 | C8: =RANDBETWEEN(1,199) -> 193 | D8: =RANK(C8,$C$4:$C$203,0)+COUNTIF($C$4:C8,C8)-1 -> 4 | E8: Quickly, she grabbed the hat. | F8: hat
B9: 6 | C9: =RANDBETWEEN(1,199) -> 62 | D9: =RANK(C9,$C$4:$C$203,0)+COUNTIF($C$4:C9,C9)-1 -> 127 | E9: The boy jumped quite high. | F9: boy
B10: 7 | C10: =RANDBETWEEN(1,199) -> 199 | D10: =RANK(C10,$C$4:$C$203,0)+COUNTIF($C$4:C10,C10)-1 -> 1 | E10: They picked up the egg. | F10: egg
B11: 8 | C11: =RANDBETWEEN(1,199) -> 73 | D11: =RANK(C11,$C$4:$C$203,0)+COUNTIF($C$4:C11,C11)-1 -> 112 | E11: A cat waited near her. | F11: cat
B12: 9 | C12: =RANDBETWEEN(1,199) -> 135 | D12: =RANK(C12,$C$4:$C$203,0)+COUNTIF($C$4:C12,C12)-1 -> 63 | E12: He dropped the pen slowly. | F12: pen
B13: 10 | C13: =RANDBETWEEN(1,199) -> 188 | D13: =RANK(C13,$C$4:$C$203,0)+COUNTIF($C$4:C13,C13)-1 -> 10 | E13: I found the fish today. | F13: fish
B14: 11 | C14: =RANDBETWEEN(1,199) -> 179 | D14: =RANK(C14,$C$4:$C$203,0)+COUNTIF($C$4:C14,C14)-1 -> 18 | E14: The goat walked very slowly. | F14: goat
B15: 12 | C15: =RANDBETWEEN(1,199) -> 167 | D15: =RANK(C15,$C$4:$C$203,0)+COUNTIF($C$4:C15,C15)-1 -> 34 | E15: She painted the wall carefully. | F15: wall
... B202: 199 | C202: =RANDBETWEEN(1,199) -> 52 | D202: =RANK(C202,$C$4:$C$203,0)+COUNTIF($C$4:C202,C202)-1 -> 139 | E202: The cat jumped quite high. | F202: cat
C203: =RANDBETWEEN(1,199) -> 12 | D203: =RANK(C203,$C$4:$C$203,0)+COUNTIF($C$4:C203,C203)-1 -> 180 | E203: I rolled the wheel down. | F203: wheel

Sheet Sheet1
C2: =RANDBETWEEN(1,100) -> 31 | D2: =RANK(C2,$C$2:$C$101,0)+COUNTIF($C$2:C2,C2)-1 -> 70 | E2: man | F2: dog | G2: book | H2: school | I2: birthday | J2: =RANDBETWEEN(1,14) -> 3 | K2: =RANK(J2,$J$2:$J$15,0)+COUNTIF($J$2:J2,J2)-1 -> 11 | L2: 1 | M2: =INDEX($E$2:$E$101,MATCH(L2,$D$2:$D$101,0)) -> painter | P2: =RANDBETWEEN(1,118) -> 107 | Q2: =RANK(P2,$P$2:$P$119,0)+COUNTIF($P$2:P2,P2)-1 -> 7 | R2: man | S2: Jose Rizal | U2: =RANDBETWEEN(1,10) -> 1 | V2: =RANK(U2,$U$2:$U$11,0)+COUNTIF($U$2:U2,U2)-1 -> 9 | W2: 1 | X2: =INDEX($S$2:$S$119,MATCH(W2,$Q$2:$Q$119,0)) -> Vice Ganda
C3: =RANDBETWEEN(1,100) -> 61 | D3: =RANK(C3,$C$2:$C$101,0)+COUNTIF($C$2:C3,C3)-1 -> 44 | E3: woman | F3: cat | G3: pen | H3: hospital | I3: wedding | J3: =RANDBETWEEN(1,14) -> 4 | K3: =RANK(J3,$J$2:$J$15,0)+COUNTIF($J$2:J3,J3)-1 -> 9 | L3: 2 | M3: =INDEX($E$2:$E$101,MATCH(L3,$D$2:$D$101,0)) -> nurse | P3: =RANDBETWEEN(1,118) -> 77 | Q3: =RANK(P3,$P$2:$P$119,0)+COUNTIF($P$2:P3,P3)-1 -> 40 | R3: woman | S3: Andres Bonifacio | U3: =RANDBETWEEN(1,10) -> 3 | V3: =RANK(U3,$U$2:$U$11,0)+COUNTIF($U$2:U3,U3)-1 -> 6 | W3: 2 | X3: =INDEX($S$2:$S$119,MATCH(W3,$Q$2:$Q$119,0)) -> Mount Apo
C4: =RANDBETWEEN(1,100) -> 64 | D4: =RANK(C4,$C$2:$C$101,0)+COUNTIF($C$2:C4,C4)-1 -> 42 | E4: child | F4: cow | G4: pencil | H4: market | I4: funeral | J4: =RANDBETWEEN(1,14) -> 1 | K4: =RANK(J4,$J$2:$J$15,0)+COUNTIF($J$2:J4,J4)-1 -> 13 | L4: 3 | M4: =INDEX($E$2:$E$101,MATCH(L4,$D$2:$D$101,0)) -> photographer | P4: =RANDBETWEEN(1,118) -> 63 | Q4: =RANK(P4,$P$2:$P$119,0)+COUNTIF($P$2:P4,P4)-1 -> 51 | R4: child | S4: Emilio Aguinaldo | U4: =RANDBETWEEN(1,10) -> 6 | V4: =RANK(U4,$U$2:$U$11,0)+COUNTIF($U$2:U4,U4)-1 -> 4 | W4: 3 | X4: =INDEX($S$2:$S$119,MATCH(W4,$Q$2:$Q$119,0)) -> Greenbelt
C5: =RANDBETWEEN(1,100) -> 44 | D5: =RANK(C5,$C$2:$C$101,0)+COUNTIF($C$2:C5,C5)-1 -> 59 | E5: boy | F5: horse | G5: eraser | H5: park | I5: anniversary | J5: =RANDBETWEEN(1,14) -> 2 | K5: =RANK(J5,$J$2:$J$15,0)+COUNTIF($J$2:J5,J5)-1 -> 12 | L5: 1 | M5: =INDEX($F$2:$F$101,MATCH(L5,$D$2:$D$101,0)) -> ant | P5: =RANDBETWEEN(1,118) -> 77 | Q5: =RANK(P5,$P$2:$P$119,0)+COUNTIF($P$2:P5,P5)-1 -> 41 | R5: teacher | S5: Manny Pacquiao | U5: =RANDBETWEEN(1,10) -> 3 | V5: =RANK(U5,$U$2:$U$11,0)+COUNTIF($U$2:U5,U5)-1 -> 7 | W5: 4 | X5: =INDEX($S$2:$S$119,MATCH(W5,$Q$2:$Q$119,0)) -> EDSA People Power Revolution
C6: =RANDBETWEEN(1,100) -> 93 | D6: =RANK(C6,$C$2:$C$101,0)+COUNTIF($C$2:C6,C6)-1 -> 6 | E6: girl | F6: goat | G6: notebook | H6: bank | I6: graduation | J6: =RANDBETWEEN(1,14) -> 10 | K6: =RANK(J6,$J$2:$J$15,0)+COUNTIF($J$2:J6,J6)-1 -> 2 | L6: 2 | M6: =INDEX($F$2:$F$101,MATCH(L6,$D$2:$D$101,0)) -> duck | P6: =RANDBETWEEN(1,118) -> 36 | Q6: =RANK(P6,$P$2:$P$119,0)+COUNTIF($P$2:P6,P6)-1 -> 85 | R6: student | S6: Lea Salonga | U6: =RANDBETWEEN(1,10) -> 5 | V6: =RANK(U6,$U$2:$U$11,0)+COUNTIF($U$2:U6,U6)-1 -> 5 | W6: 5 | X6: =INDEX($S$2:$S$119,MATCH(W6,$Q$2:$Q$119,0)) -> Marry Pauline T. Martin
C7: =RANDBETWEEN(1,100) -> 90 | D7: =RANK(C7,$C$2:$C$101,0)+COUNTIF($C$2:C7,C7)-1 -> 11 | E7: teacher | F7: sheep | G7: bag | H7: library | I7: party | J7: =RANDBETWEEN(1,14) -> 12 | K7: =RANK(J7,$J$2:$J$15,0)+COUNTIF($J$2:J7,J7)-1 -> 1 | L7: 3 | M7: =INDEX($F$2:$F$101,MATCH(L7,$D$2:$D$101,0)) -> flamingo | P7: =RANDBETWEEN(1,118) -> 76 | Q7: =RANK(P7,$P$2:$P$119,0)+COUNTIF($P$2:P7,P7)-1 -> 44 | R7: doctor | S7: Liza Soberano | U7: =RANDBETWEEN(1,10) -> 3 | V7: =RANK(U7,$U$2:$U$11,0)+COUNTIF($U$2:U7,U7)-1 -> 8 | W7: 1 | X7: =INDEX($R$2:$R$119,MATCH(W7,$Q$2:$Q$119,0)) -> nurse
C8: =RANDBETWEEN(1,100) -> 29 | D8: =RANK(C8,$C$2:$C$101,0)+COUNTIF($C$2:C8,C8)-1 -> 73 | E8: student | F8: pig | G8: box | H8: restaurant | I8: festival | J8: =RANDBETWEEN(1,14) -> 1 | K8: =RANK(J8,$J$2:$J$15,0)+COUNTIF($J$2:J8,J8)-1 -> 14 | L8: 1 | M8: =INDEX($G$2:$G$101,MATCH(L8,$D$2:$D$101,0)) -> shoes | P8: =RANDBETWEEN(1,118) -> 118 | Q8: =RANK(P8,$P$2:$P$119,0)+COUNTIF($P$2:P8,P8)-1 -> 1 | R8: nurse | S8: Vice Ganda | U8: =RANDBETWEEN(1,10) -> 7 | V8: =RANK(U8,$U$2:$U$11,0)+COUNTIF($U$2:U8,U8)-1 -> 2 | W8: 2 | X8: =INDEX($R$2:$R$119,MATCH(W8,$Q$2:$Q$119,0)) -> neighbor
C9: =RANDBETWEEN(1,100) -> 78 | D9: =RANK(C9,$C$2:$C$101,0)+COUNTIF($C$2:C9,C9)-1 -> 22 | E9: doctor | F9: chicken | G9: chair | H9: hotel | I9: holiday | J9: =RANDBETWEEN(1,14) -> 7 | K9: =RANK(J9,$J$2:$J$15,0)+COUNTIF($J$2:J9,J9)-1 -> 6 | L9: 2 | M9: =INDEX($G$2:$G$101,MATCH(L9,$D$2:$D$101,0)) -> table | P9: =RANDBETWEEN(1,118) -> 37 | Q9: =RANK(P9,$P$2:$P$119,0)+COUNTIF($P$2:P9,P9)-1 -> 83 | R9: driver | S9: Ninoy Aquino | U9: =RANDBETWEEN(1,10) -> 8 | V9: =RANK(U9,$U$2:$U$11,0)+COUNTIF($U$2:U9,U9)-1 -> 1 | W9: 3 | X9: =INDEX($R$2:$R$119,MATCH(W9,$Q$2:$Q$119,0)) -> cashier
C10: =RANDBETWEEN(1,100) -> 98 | D10: =RANK(C10,$C$2:$C$101,0)+COUNTIF($C$2:C10,C10)-1 -> 2 | E10: nurse | F10: duck | G10: table | H10: airport | I10: meeting | J10: =RANDBETWEEN(1,14) -> 4 | K10: =RANK(J10,$J$2:$J$15,0)+COUNTIF($J$2:J10,J10)-1 -> 10 | L10: 3 | M10: =INDEX($G$2:$G$101,MATCH(L10,$D$2:$D$101,0)) -> needle | P10: =RANDBETWEEN(1,118) -> 37 | Q10: =RANK(P10,$P$2:$P$119,0)+COUNTIF($P$2:P10,P10)-1 -> 84 | R10: farmer | S10: Cory Aquino | U10: =RANDBETWEEN(1,10) -> 1 | V10: =RANK(U10,$U$2:$U$11,0)+COUNTIF($U$2:U10,U10)-1 -> 10 | W10: 4 | X10: =INDEX($R$2:$R$119,MATCH(W10,$Q$2:$Q$119,0)) -> computer
C11: =RANDBETWEEN(1,100) -> 93 | D11: =RANK(C11,$C$2:$C$101,0)+COUNTIF($C$2:C11,C11)-1 -> 7 | E11: farmer | F11: goose | G11: desk | H11: station | I11: interview | J11: =RANDBETWEEN(1,14) -> 9 | K11: =RANK(J11,$J$2:$J$15,0)+COUNTIF($J$2:J11,J11)-1 -> 5 | L11: 1 | M11: =INDEX($H$2:$H$101,MATCH(L11,$D$2:$D$101,0)) -> subway | P11: =RANDBETWEEN(1,118) -> 95 | Q11: =RANK(P11,$P$2:$P$119,0)+COUNTIF($P$2:P11,P11)-1 -> 19 | R11: artist | S11: Leni Robredo | U11: =RANDBETWEEN(1,10) -> 7 | V11: =RANK(U11,$U$2:$U$11,0)+COUNTIF($U$2:U11,U11)-1 -> 3 | W11: 5 | X11: =INDEX($R$2:$R$119,MATCH(W11,$Q$2:$Q$119,0)) -> street
C12: =RANDBETWEEN(1,100) -> 75 | D12: =RANK(C12,$C$2:$C$101,0)+COUNTIF($C$2:C12,C12)-1 -> 26 | E12: driver | F12: donkey | G12: lamp | H12: zoo | I12: ceremony | J12: =RANDBETWEEN(1,14) -> 10 | K12: =RANK(J12,$J$2:$J$15,0)+COUNTIF($J$2:J12,J12)-1 -> 3 | L12: 2 | M12: =INDEX($H$2:$H$101,MATCH(L12,$D$2:$D$101,0)) -> airport | P12: =RANDBETWEEN(1,118) -> 96 | Q12: =RANK(P12,$P$2:$P$119,0)+COUNTIF($P$2:P12,P12)-1 -> 18 | R12: singer | S12: Rodrigo Duterte
C13: =RANDBETWEEN(1,100) -> 77 | D13: =RANK(C13,$C$2:$C$101,0)+COUNTIF($C$2:C13,C13)-1 -> 23 | E13: artist | F13: rabbit | G13: fan | H13: museum | I13: parade | J13: =RANDBETWEEN(1,14) -> 5 | K13: =RANK(J13,$J$2:$J$15,0)+COUNTIF($J$2:J13,J13)-1 -> 7 | L13: 3 | M13: =INDEX($H$2:$H$101,MATCH(L13,$D$2:$D$101,0)) -> restaurant | P13: =RANDBETWEEN(1,118) -> 64 | Q13: =RANK(P13,$P$2:$P$119,0)+COUNTIF($P$2:P13,P13)-1 -> 50 | R13: dancer | S13: Ferdinand Marcos
C14: =RANDBETWEEN(1,100) -> 15 | D14: =RANK(C14,$C$2:$C$101,0)+COUNTIF($C$2:C14,C14)-1 -> 90 | E14: singer | F14: deer | G14: clock | H14: church | I14: concert | J14: =RANDBETWEEN(1,14) -> 5 | K14: =RANK(J14,$J$2:$J$15,0)+COUNTIF($J$2:J14,J14)-1 -> 8 | L14: 1 | M14: =INDEX($I$2:$I$101,MATCH(L14,$D$2:$D$101,0)) -> release | P14: =RANDBETWEEN(1,118) -> 59 | Q14: =RANK(P14,$P$2:$P$119,0)+COUNTIF($P$2:P14,P14)-1 -> 57 | R14: writer | S14: Bongbong Marcos
C15: =RANDBETWEEN(1,100) -> 44 | D15: =RANK(C15,$C$2:$C$101,0)+COUNTIF($C$2:C15,C15)-1 -> 60 | E15: dancer | F15: camel | G15: watch | H15: mosque | I15: show | J15: =RANDBETWEEN(1,14) -> 10 | K15: =RANK(J15,$J$2:$J$15,0)+COUNTIF($J$2:J15,J15)-1 -> 4 | L15: 2 | M15: =INDEX($I$2:$I$101,MATCH(L15,$D$2:$D$101,0)) -> meeting | P15: =RANDBETWEEN(1,118) -> 48 | Q15: =RANK(P15,$P$2:$P$119,0)+COUNTIF($P$2:P15,P15)-1 -> 70 | R15: chef | S15: Kris Aquino
C16: =RANDBETWEEN(1,100) -> 84 | D16: =RANK(C16,$C$2:$C$101,0)+COUNTIF($C$2:C16,C16)-1 -> 18 | E16: writer | F16: buffalo | G16: phone | H16: temple | I16: contest | P16: =RANDBETWEEN(1,118) -> 27 | Q16: =RANK(P16,$P$2:$P$119,0)+COUNTIF($P$2:P16,P16)-1 -> 97 | R16: baker | S16: Sarah Geronimo
C17: =RANDBETWEEN(1,100) -> 2 | D17: =RANK(C17,$C$2:$C$101,0)+COUNTIF($C$2:C17,C17)-1 -> 97 | E17: poet | F17: ox | G17: television | H17: store | I17: competition | P17: =RANDBETWEEN(1,118) -> 101 | Q17: =RANK(P17,$P$2:$P$119,0)+COUNTIF($P$2:P17,P17)-1 -> 13 | R17: actor | S17: Daniel Padilla
C18: =RANDBETWEEN(1,100) -> 88 | D18: =RANK(C18,$C$2:$C$101,0)+COUNTIF($C$2:C18,C18)-1 -> 14 | E18: chef | F18: rat | G18: radio | H18: mall | I18: game | P18: =RANDBETWEEN(1,118) -> 26 | Q18: =RANK(P18,$P$2:$P$119,0)+COUNTIF($P$2:P18,P18)-1 -> 98 | R18: pilot | S18: Kathryn Bernardo
C19: =RANDBETWEEN(1,100) -> 60 | D19: =RANK(C19,$C$2:$C$101,0)+COUNTIF($C$2:C19,C19)-1 -> 45 | E19: baker | F19: mouse | G19: computer | H19: office | I19: match | P19: =RANDBETWEEN(1,118) -> 80 | Q19: =RANK(P19,$P$2:$P$119,0)+COUNTIF($P$2:P19,P19)-1 -> 36 | R19: soldier | S19: Catriona Gray
C20: =RANDBETWEEN(1,100) -> 20 | D20: =RANK(C20,$C$2:$C$101,0)+COUNTIF($C$2:C20,C20)-1 -> 85 | E20: actor | F20: bat | G20: keyboard | H20: factory | I20: race | P20: =RANDBETWEEN(1,118) -> 55 | Q20: =RANK(P20,$P$2:$P$119,0)+COUNTIF($P$2:P20,P20)-1 -> 62 | R20: police | S20: Pia Wurtzbach
C21: =RANDBETWEEN(1,100) -> 49 | D21: =RANK(C21,$C$2:$C$101,0)+COUNTIF($C$2:C21,C21)-1 -> 55 | E21: actress | F21: monkey | G21: mouse | H21: theater | I21: tournament | P21: =RANDBETWEEN(1,118) -> 104 | Q21: =RANK(P21,$P$2:$P$119,0)+COUNTIF($P$2:P21,P21)-1 -> 10 | R21: guard | S21: Gloria Macapagal Arroyo
C22: =RANDBETWEEN(1,100) -> 72 | D22: =RANK(C22,$C$2:$C$101,0)+COUNTIF($C$2:C22,C22)-1 -> 31 | E22: pilot | F22: elephant | G22: printer | H22: cinema | I22: seminar | P22: =RANDBETWEEN(1,118) -> 29 | Q22: =RANK(P22,$P$2:$P$119,0)+COUNTIF($P$2:P22,P22)-1 -> 93 | R22: lawyer | S22: Metro Manila
C23: =RANDBETWEEN(1,100) -> 25 | D23: =RANK(C23,$C$2:$C$101,0)+COUNTIF($C$2:C23,C23)-1 -> 81 | E23: soldier | F23: lion | G23: scanner | H23: playground | I23: conference | P23: =RANDBETWEEN(1,118) -> 63 | Q23: =RANK(P23,$P$2:$P$119,0)+COUNTIF($P$2:P23,P23)-1 -> 52 | R23: judge | S23: Quezon City
C24: =RANDBETWEEN(1,100) -> 28 | D24: =RANK(C24,$C$2:$C$101,0)+COUNTIF($C$2:C24,C24)-1 -> 76 | E24: police | F24: tiger | G24: bottle | H24: farm | I24: workshop | P24: =RANDBETWEEN(1,118) -> 21 | Q24: =RANK(P24,$P$2:$P$119,0)+COUNTIF($P$2:P24,P24)-1 -> 104 | R24: scientist | S24: Makati City
C25: =RANDBETWEEN(1,100) -> 66 | D25: =RANK(C25,$C$2:$C$101,0)+COUNTIF($C$2:C25,C25)-1 -> 41 | E25: guard | F25: bear | G25: glass | H25: garden | I25: webinar | P25: =RANDBETWEEN(1,118) -> 58 | Q25: =RANK(P25,$P$2:$P$119,0)+COUNTIF($P$2:P25,P25)-1 -> 58 | R25: athlete | S25: Manila
C26: =RANDBETWEEN(1,100) -> 26 | D26: =RANK(C26,$C$2:$C$101,0)+COUNTIF($C$2:C26,C26)-1 -> 79 | E26: lawyer | F26: wolf | G26: cup | H26: kitchen | I26: reunion | P26: =RANDBETWEEN(1,118) -> 94 | Q26: =RANK(P26,$P$2:$P$119,0)+COUNTIF($P$2:P26,P26)-1 -> 22 | R26: player | S26: Cebu City
C27: =RANDBETWEEN(1,100) -> 43 | D27: =RANK(C27,$C$2:$C$101,0)+COUNTIF($C$2:C27,C27)-1 -> 62 | E27: judge | F27: fox | G27: plate | H27: bedroom | I27: farewell | P27: =RANDBETWEEN(1,118) -> 39 | Q27: =RANK(P27,$P$2:$P$119,0)+COUNTIF($P$2:P27,P27)-1 -> 79 | R27: coach | S27: Davao City
... C101: =RANDBETWEEN(1,100) -> 19 | D101: =RANK(C101,$C$2:$C$101,0)+COUNTIF($C$2:C101,C101)-1 -> 88 | E101: adult | F101: porcupine | G101: map | H101: barbershop | I101: report | P101: =RANDBETWEEN(1,118) -> 56 | Q101: =RANK(P101,$P$2:$P$119,0)+COUNTIF($P$2:P101,P101)-1 -> 61 | R101: car | S101: Masbate City
G102: flag | H102: pharmacy | I102: presentation | P102: =RANDBETWEEN(1,118) -> 32 | Q102: =RANK(P102,$P$2:$P$119,0)+COUNTIF($P$2:P102,P102)-1 -> 91 | R102: bus | S102: Roxas City Capiz
G103: gift | H103: schoolyard | I103: demonstration | P103: =RANDBETWEEN(1,118) -> 86 | Q103: =RANK(P103,$P$2:$P$119,0)+COUNTIF($P$2:P103,P103)-1 -> 32 | R103: train | S103: Jhamila S. Santos
G104: lamp | H104: crosswalk | I104: launching | P104: =RANDBETWEEN(1,118) -> 22 | Q104: =RANK(P104,$P$2:$P$119,0)+COUNTIF($P$2:P104,P104)-1 -> 103 | R104: road | S104: Stephanie E. Dela Cruz
G105: candle | H105: roundabout | I105: enrollment | P105: =RANDBETWEEN(1,118) -> 113 | Q105: =RANK(P105,$P$2:$P$119,0)+COUNTIF($P$2:P105,P105)-1 -> 5 | R105: street | S105: Marry Pauline T. Martin
I106: application | P106: =RANDBETWEEN(1,118) -> 46 | Q106: =RANK(P106,$P$2:$P$119,0)+COUNTIF($P$2:P106,P106)-1 -> 75 | R106: chair | S106: Mayca S. Bernardo
P107: =RANDBETWEEN(1,118) -> 18 | Q107: =RANK(P107,$P$2:$P$119,0)+COUNTIF($P$2:P107,P107)-1 -> 108 | R107: table | S107: Mary Rose B. Cruz
P108: =RANDBETWEEN(1,118) -> 98 | Q108: =RANK(P108,$P$2:$P$119,0)+COUNTIF($P$2:P108,P108)-1 -> 15 | R108: dog | S108: Jade Andrea Dizon
P109: =RANDBETWEEN(1,118) -> 41 | Q109: =RANK(P109,$P$2:$P$119,0)+COUNTIF($P$2:P109,P109)-1 -> 77 | R109: cat | S109: Rose Swares
P110: =RANDBETWEEN(1,118) -> 84 | Q110: =RANK(P110,$P$2:$P$119,0)+COUNTIF($P$2:P110,P110)-1 -> 34 | R110: tiger | S110: Jasmine Padilla
P111: =RANDBETWEEN(1,118) -> 92 | Q111: =RANK(P111,$P$2:$P$119,0)+COUNTIF($P$2:P111,P111)-1 -> 27 | R111: book | S111: Stephen Clarck Davao
P112: =RANDBETWEEN(1,118) -> 18 | Q112: =RANK(P112,$P$2:$P$119,0)+COUNTIF($P$2:P112,P112)-1 -> 109 | R112: pen | S112: Zian G. Legaspi
P113: =RANDBETWEEN(1,118) -> 17 | Q113: =RANK(P113,$P$2:$P$119,0)+COUNTIF($P$2:P113,P113)-1 -> 112 | R113: lamp | S113: Alex S. Smith
P114: =RANDBETWEEN(1,118) -> 74 | Q114: =RANK(P114,$P$2:$P$119,0)+COUNTIF($P$2:P114,P114)-1 -> 46 | R114: candle | S114: Daryl L. Wung
...
